Workbook

Sheet Responses
A1: Submission ID | B1: Respondent ID | C1: Submitted At | D1: Nama | E1: Kelas | F1: Umur | G1: SDQ Q1 | H1: SDQ Q2 | I1: SDQ Q3 | J1: SDQ Q4 | K1: SDQ Q5 | L1: SDQ Q6 | M1: SDQ Q7(R) | N1: SDQ Q8 | O1: SDQ Q9 | P1: SDQ Q10 | Q1: SDQ Q11(R) | R1: SDQ Q12 | S1: SDQ Q13 | T1: SDQ Q14(R) | U1: SDQ Q15 | V1: SDQ Q16 | W1: SDQ Q17 | X1: SDQ Q18 | Y1: SDQ Q19 | Z1: SDQ Q20 | AA1: SDQ Q21(R) | AB1: SDQ Q22 | AC1: SDQ Q23 | AD1: SDQ Q24 | AE1: SDQ Q25(R) | AF1: IAA Q1 | AG1: IAA Q2 | AH1: IAA Q3 | AI1: IAA Q4 | AJ1: IAA Q5 | AK1: IAA Q6 | AL1: IAA Q7 | AM1: IAA Q8 | AN1: IAA Q9 | AO1: IAA Q10 | AP1: IAA Q11 | AQ1: IAA Q12 | AR1: IAA Q13 | AS1: IAA Q14 | AT1: IAA Q15 | AU1: IAA Q16 | AV1: IAA Q17 | AW1: IAA Q18
A2: rDaeWjv | B2: GxoM0Oz | C2: 46136.091 | D2: Farasafa Alzeta | E2: XI-1 | F2: 17 | G2: Benar | H2: Benar | I2: Benar | J2: Benar | K2: Agak Benar | L2: Agak Benar | M2: Agak Benar | N2: Benar | O2: Agak Benar | P2: Benar | Q2: Benar | R2: Agak Benar | S2: Benar | T2: Agak Benar | U2: Agak Benar | V2: Agak Benar | W2: Agak Benar | X2: Agak Benar | Y2: Tidak Benar | Z2: Agak Benar | AA2: Benar | AB2: Tidak Benar | AC2: Agak Benar | AD2: Benar | AE2: Benar | AF2: Sering | AG2: Kadang - Kadang | AH2: Kadang - Kadang | AI2: Jarang | AJ2: Jarang | AK2: Kadang - Kadang | AL2: Jarang | AM2: Kadang - Kadang | AN2: Kadang - Kadang | AO2: Kadang - Kadang | AP2: Sering | AQ2: Selalu | AR2: Kadang - Kadang | AS2: Kadang - Kadang | AT2: Kadang - Kadang | AU2: Jarang | AV2: Kadang - Kadang | AW2: Sering
A3: gbdE1PN | B3: XxRjYOd | C3: 46136.091 | D3: Habibah Putri Kawiswara | E3: XI-1 | F3: 11 | G3: Benar | H3: Agak Benar | I3: Benar | J3: Agak Benar | K3: Agak Benar | L3: Benar | M3: Benar | N3: Agak Benar | O3: Agak Benar | P3: Benar | Q3: Benar | R3: Tidak Benar | S3: Agak Benar | T3: Tidak Benar | U3: Agak Benar | V3: Benar | W3: Benar | X3: Tidak Benar | Y3: Tidak Benar | Z3: Benar | AA3: Agak Benar | AB3: Tidak Benar | AC3: Tidak Benar | AD3: Agak Benar | AE3: Tidak Benar | AF3: Selalu | AG3: Selalu | AH3: Selalu | AI3: Kadang - Kadang | AJ3: Selalu | AK3: Tidak Pernah | AL3: Kadang - Kadang | AM3: Sering | AN3: Tidak Pernah | AO3: Selalu | AP3: Selalu | AQ3: Jarang | AR3: Sering | AS3: Tidak Pernah | AT3: Sering | AU3: Jarang | AV3: Selalu | AW3: Tidak Pernah
A4: M1NW2Ol | B4: VL9r1r6 | C4: 46136.092 | D4: Julian | E4: XI-1 | F4: 16 | G4: Benar | H4: Benar | I4: Tidak Benar | J4: Agak Benar | K4: Tidak Benar | L4: Benar | M4: Tidak Benar | N4: Tidak Benar | O4: Benar | P4: Tidak Benar | Q4: Benar | R4: Tidak Benar | S4: Tidak Benar | T4: Agak Benar | U4: Tidak Benar | V4: Tidak Benar | W4: Benar | X4: Tidak Benar | Y4: Tidak Benar | Z4: Agak Benar | AA4: Benar | AB4: Tidak Benar | AC4: Tidak Benar | AD4: Tidak Benar | AE4: Agak Benar | AF4: Kadang - Kadang | AG4: Sering | AH4: Sering | AI4: Tidak Pernah | AJ4: Jarang | AK4: Selalu | AL4: Tidak Pernah | AM4: Sering | AN4: Jarang | AO4: Jarang | AP4: Tidak Pernah | AQ4: Jarang | AR4: Kadang - Kadang | AS4: Tidak Pernah | AT4: Jarang | AU4: Sering | AV4: Jarang | AW4: Tidak Pernah
A5: 9N98jAV | B5: RGZObRK | C5: 46136.092 | D5: Qori Ilyasa Fariduddin Purwadi | E5: XI-1 | F5: 17 | G5: Agak Benar | H5: Tidak Benar | I5: Benar | J5: Benar | K5: Agak Benar | L5: Agak Benar | M5: Agak Benar | N5: Benar | O5: Benar | P5: Benar | Q5: Agak Benar | R5: Agak Benar | S5: Benar | T5: Tidak Benar | U5: Benar | V5: Agak Benar | W5: Benar | X5: Agak Benar | Y5: Agak Benar | Z5: Benar | AA5: Benar | AB5: Tidak Benar | AC5: Benar | AD5: Benar | AE5: Tidak Benar | AF5: Jarang | AG5: Kadang - Kadang | AH5: Jarang | AI5: Selalu | AJ5: Tidak Pernah | AK5: Selalu | AL5: Kadang - Kadang | AM5: Tidak Pernah | AN5: Tidak Pernah | AO5: Jarang | AP5: Selalu | AQ5: Jarang | AR5: Jarang | AS5: Kadang - Kadang | AT5: Jarang | AU5: Tidak Pernah | AV5: Kadang - Kadang | AW5: Tidak Pernah
A6: Eqd2RJ2 | B6: EkBpN2L | C6: 46136.093 | D6: Kirana Annisa Noegroho | E6: XI-1 | F6: 16 | G6: Benar | H6: Benar | I6: Tidak Benar | J6: Agak Benar | K6: Tidak Benar | L6: Tidak Benar | M6: Agak Benar | N6: Agak Benar | O6: Agak Benar | P6: Benar | Q6: Benar | R6: Tidak Benar | S6: Tidak Benar | T6: Benar | U6: Tidak Benar | V6: Agak Benar | W6: Agak Benar | X6: Tidak Benar | Y6: Tidak Benar | Z6: Agak Benar | AA6: Agak Benar | AB6: Tidak Benar | AC6: Tidak Benar | AD6: Agak Benar | AE6: Benar | AF6: Sering | AG6: Jarang | AH6: Kadang - Kadang | AI6: Tidak Pernah | AJ6: Tidak Pernah | AK6: Jarang | AL6: Tidak Pernah | AM6: Selalu | AN6: Jarang | AO6: Kadang - Kadang | AP6: Kadang - Kadang | AQ6: Sering | AR6: Jarang | AS6: Sering | AT6: Kadang - Kadang | AU6: Kadang - Kadang | AV6: Jarang | AW6: Kadang - Kadang
A7: BEdrr21 | B7: Np4zdeW | C7: 46136.093 | D7: Raffarel Jozka Dafiq Prihantara | E7: XI-1 | F7: 16 | G7: Benar | H7: Benar | I7: Tidak Benar | J7: Benar | K7: Agak Benar | L7: Tidak Benar | M7: Tidak Benar | N7: Tidak Benar | O7: Benar | P7: Agak Benar | Q7: Benar | R7: Tidak Benar | S7: Tidak Benar | T7: Benar | U7: Agak Benar | V7: Agak Benar | W7: Benar | X7: Tidak Benar | Y7: Tidak Benar | Z7: Benar | AA7: Benar | AB7: Tidak Benar | AC7: Benar | AD7: Tidak Benar | AE7: Benar | AF7: Kadang - Kadang | AG7: Jarang | AH7: Jarang | AI7: Tidak Pernah | AJ7: Tidak Pernah | AK7: Tidak Pernah | AL7: Tidak Pernah | AM7: Jarang | AN7: Jarang | AO7: Selalu | AP7: Kadang - Kadang | AQ7: Sering | AR7: Jarang | AS7: Kadang - Kadang | AT7: Sering | AU7: Tidak Pernah | AV7: Tidak Pernah | AW7: Jarang
A8: M1NW06g | B8: vG0Rzk0 | C8: 46136.093 | D8: Salwa Nafisatul Khoerun Nisa | E8: XI-1 | F8: 17 | G8: Benar | H8: Agak Benar | I8: Benar | J8: Benar | K8: Tidak Benar | L8: Benar | M8: Benar | N8: Benar | O8: Benar | P8: Benar | Q8: Benar | R8: Tidak Benar | S8: Agak Benar | T8: Benar | U8: Agak Benar | V8: Benar | W8: Benar | X8: Tidak Benar | Y8: Tidak Benar | Z8: Benar | AA8: Benar | AB8: Tidak Benar | AC8: Tidak Benar | AD8: Benar | AE8: Benar | AF8: Sering | AG8: Kadang - Kadang | AH8: Jarang | AI8: Jarang | AJ8: Tidak Pernah | AK8: Tidak Pernah | AL8: Kadang - Kadang | AM8: Kadang - Kadang | AN8: Tidak Pernah | AO8: Kadang - Kadang | AP8: Tidak Pernah | AQ8: Sering | AR8: Sering | AS8: Kadang - Kadang | AT8: Tidak Pernah | AU8: Jarang | AV8: Kadang - Kadang | AW8: Jarang
A9: zEykPxa | B9: VL9rq96 | C9: 46136.093 | D9: Najwa Alya Puteri | E9: XI-1 | F9: 17 | G9: Benar | H9: Tidak Benar | I9: Benar | J9: Agak Benar | K9: Agak Benar | L9: Agak Benar | M9: Agak Benar | N9: Agak Benar | O9: Benar | P9: Tidak Benar | Q9: Benar | R9: Agak Benar | S9: Agak Benar | T9: Tidak Benar | U9: Tidak Benar | V9: Benar | W9: Agak Benar | X9: Agak Benar | Y9: Benar | Z9: Benar | AA9: Benar | AB9: Tidak Benar | AC9: Agak Benar | AD9: Agak Benar | AE9: Agak Benar | AF9: Sering | AG9: Jarang | AH9: Kadang - Kadang | AI9: Sering | AJ9: Selalu | AK9: Jarang | AL9: Jarang | AM9: Kadang - Kadang | AN9: Kadang - Kadang | AO9: Jarang | AP9: Sering | AQ9: Kadang - Kadang | AR9: Kadang - Kadang | AS9: Kadang - Kadang | AT9: Kadang - Kadang | AU9: Kadang - Kadang | AV9: Kadang - Kadang | AW9: Kadang - Kadang
A10: BEdrMd7 | B10: Mer0P6k | C10: 46136.093 | D10: Syarifah Lutfia Varisha | E10: XI-1 | F10: 17 | G10: Benar | H10: Benar | I10: Agak Benar | J10: Agak Benar | K10: Agak Benar | L10: Tidak Benar | M10: Benar | N10: Benar | O10: Benar | P10: Benar | Q10: Benar | R10: Tidak Benar | S10: Agak Benar | T10: Benar | U10: Agak Benar | V10: Agak Benar | W10: Benar | X10: Agak Benar | Y10: Tidak Benar | Z10: Benar | AA10: Benar | AB10: Tidak Benar | AC10: Tidak Benar | AD10: Agak Benar | AE10: Agak Benar | AF10: Sering | AG10: Kadang - Kadang | AH10: Kadang - Kadang | AI10: Jarang | AJ10: Sering | AK10: Kadang - Kadang | AL10: Kadang - Kadang | AM10: Kadang - Kadang | AN10: Jarang | AO10: Sering | AP10: Selalu | AQ10: Sering | AR10: Kadang - Kadang | AS10: Kadang - Kadang | AT10: Kadang - Kadang | AU10: Kadang - Kadang | AV10: Jarang | AW10: Sering
A11: NqlaGMj | B11: ob0JgPM | C11: 46136.094 | D11: Bella Khalwanina Arastya | E11: XI-1 | F11: 18 | G11: Benar | H11: Tidak Benar | I11: Agak Benar | J11: Agak Benar | K11: Tidak Benar | L11: Benar | M11: Benar | N11: Agak Benar | O11: Benar | P11: Agak Benar | Q11: Benar | R11: Tidak Benar | S11: Agak Benar | T11: Agak Benar | U11: Tidak Benar | V11: Agak Benar | W11: Benar | X11: Tidak Benar | Y11: Tidak Benar | Z11: Benar | AA11: Benar | AB11: Tidak Benar | AC11: Agak Benar | AD11: Agak Benar | AE11: Benar | AF11: Sering | AG11: Kadang - Kadang | AH11: Sering | AI11: Jarang | AJ11: Sering | AK11: Jarang | AL11: Jarang | AM11: Tidak Pernah | AN11: Kadang - Kadang | AO11: Kadang - Kadang | AP11: Kadang - Kadang | AQ11: Jarang | AR11: Jarang | AS11: Tidak Pernah | AT11: Kadang - Kadang | AU11: Kadang - Kadang | AV11: Kadang - Kadang | AW11: Tidak Pernah
A12: e5QVkve | B12: RGZO2Ov | C12: 46136.094 | D12: Nabila Putri Herawati | E12: XI-1 | F12: 16 | G12: Benar | H12: Agak Benar | I12: Tidak Benar | J12: Benar | K12: Tidak Benar | L12: Tidak Benar | M12: Benar | N12: Tidak Benar | O12: Benar | P12: Tidak Benar | Q12: Benar | R12: Tidak Benar | S12: Tidak Benar | T12: Benar | U12: Tidak Benar | V12: Agak Benar | W12: Benar | X12: Tidak Benar | Y12: Tidak Benar | Z12: Benar | AA12: Benar | AB12: Tidak Benar | AC12: Tidak Benar | AD12: Agak Benar | AE12: Benar | AF12: Kadang - Kadang | AG12: Tidak Pernah | AH12: Tidak Pernah | AI12: Jarang | AJ12: Tidak Pernah | AK12: Tidak Pernah | AL12: Tidak Pernah | AM12: Kadang - Kadang | AN12: Tidak Pernah | AO12: Sering | AP12: Tidak Pernah | AQ12: Tidak Pernah | AR12: Tidak Pernah | AS12: Jarang | AT12: Kadang - Kadang | AU12: Tidak Pernah | AV12: Kadang - Kadang | AW12: Jarang
A13: kbe2MX6 | B13: dWZ7pEd | C13: 46136.094 | D13: Arsyita | E13: XI-1 | F13: 16 | G13: Benar | H13: Tidak Benar | I13: Agak Benar | J13: Benar | K13: Agak Benar | L13: Tidak Benar | M13: Agak Benar | N13: Tidak Benar | O13: Benar | P13: Tidak Benar | Q13: Benar | R13: Tidak Benar | S13: Agak Benar | T13: Benar | U13: Agak Benar | V13: Tidak Benar | W13: Agak Benar | X13: Tidak Benar | Y13: Tidak Benar | Z13: Agak Benar | AA13: Agak Benar | AB13: Tidak Benar | AC13: Tidak Benar | AD13: Agak Benar | AE13: Agak Benar | AF13: Selalu | AG13: Kadang - Kadang | AH13: Sering | AI13: Jarang | AJ13: Jarang | AK13: Tidak Pernah | AL13: Jarang | AM13: Jarang | AN13: Jarang | AO13: Kadang - Kadang | AP13: Kadang - Kadang | AQ13: Sering | AR13: Sering | AS13: Jarang | AT13: Jarang | AU13: Jarang | AV13: Kadang - Kadang | AW13: Tidak Pernah
... A127: Gepxgbz | B127: zxWENP0 | C127: 46136.156 | D127: Safira Rahma Rajabiya | E127: XI-2 | F127: 16 | G127: Benar | H127: Tidak Benar | I127: Agak Benar | J127: Agak Benar | K127: Agak Benar | L127: Tidak Benar | M127: Agak Benar | N127: Agak Benar | O127: Benar | P127: Agak Benar | Q127: Benar | R127: Tidak Benar | S127: Agak Benar | T127: Agak Benar | U127: Tidak Benar | V127: Agak Benar | W127: Benar | X127: Tidak Benar | Y127: Tidak Benar | Z127: Benar | AA127: Benar | AB127: Tidak Benar | AC127: Agak Benar | AD127: Benar | AE127: Benar | AF127: Sering | AG127: Kadang - Kadang | AH127: Sering | AI127: Jarang | AJ127: Kadang - Kadang | AK127: Jarang | AL127: Sering | AM127: Sering | AN127: Tidak Pernah | AO127: Kadang - Kadang | AP127: Jarang | AQ127: Kadang - Kadang | AR127: Sering | AS127: Jarang | AT127: Tidak Pernah | AU127: Kadang - Kadang | AV127: Jarang | AW127: Jarang

Sheet SDQ_Scores
A1: Submission ID | B1: Respondent ID | C1: Submitted At | D1: Nama | E1: Kelas | F1: Umur | G1: Skor Q1 | H1: Skor Q2 | I1: Skor Q3 | J1: Skor Q4 | K1: Skor Q5 | L1: Skor Q6 | M1: Skor Q7(R) | N1: Skor Q8 | O1: Skor Q9 | P1: Skor Q10 | Q1: Skor Q11(R) | R1: Skor Q12 | S1: Skor Q13 | T1: Skor Q14(R) | U1: Skor Q15 | V1: Skor Q16 | W1: Skor Q17 | X1: Skor Q18 | Y1: Skor Q19 | Z1: Skor Q20 | AA1: Skor Q21(R) | AB1: Skor Q22 | AC1: Skor Q23 | AD1: Skor Q24 | AE1: Skor Q25(R) | AF1: Skor E Gejala Emosional | AG1: Skor C Masalah Perilaku | AH1: Skor H Hiperaktivitas | AI1: Skor P Masalah Teman Sebaya | AJ1: Skor Pr Prososial | AK1: Status E Gejala Emosional | AL1: Status C Masalah Perilaku | AM1: Status H Hiperaktivitas | AN1: Status P Masalah Teman Sebaya | AO1: Status Pr Prososial | AP1: Total Kesulitan | AQ1: Status SDQ (Kemenkes)
A2: =Responses!A2 -> rDaeWjv | B2: =Responses!B2 -> GxoM0Oz | C2: =Responses!C2 -> 46136.091 | D2: =Responses!D2 -> Farasafa Alzeta | E2: =Responses!E2 -> XI-1 | F2: =Responses!F2 -> 17 | G2: =IF(Responses!G2="","",IF(Responses!G2="Benar",2,IF(Responses!G2="Agak Benar",1,0))) -> 2 | H2: =IF(Responses!H2="","",IF(Responses!H2="Benar",2,IF(Responses!H2="Agak Benar",1,0))) -> 2 | I2: =IF(Responses!I2="","",IF(Responses!I2="Benar",2,IF(Responses!I2="Agak Benar",1,0))) -> 2 | J2: =IF(Responses!J2="","",IF(Responses!J2="Benar",2,IF(Responses!J2="Agak Benar",1,0))) -> 2 | K2: =IF(Responses!K2="","",IF(Responses!K2="Benar",2,IF(Responses!K2="Agak Benar",1,0))) -> 1 | L2: =IF(Responses!L2="","",IF(Responses!L2="Benar",2,IF(Responses!L2="Agak Benar",1,0))) -> 1 | M2: =IF(Responses!M2="","",IF(Responses!M2="Tidak Benar",2,IF(Responses!M2="Agak Benar",1,0))) -> 1 | N2: =IF(Responses!N2="","",IF(Responses!N2="Benar",2,IF(Responses!N2="Agak Benar",1,0))) -> 2 | O2: =IF(Responses!O2="","",IF(Responses!O2="Benar",2,IF(Responses!O2="Agak Benar",1,0))) -> 1 | P2: =IF(Responses!P2="","",IF(Responses!P2="Benar",2,IF(Responses!P2="Agak Benar",1,0))) -> 2 | Q2: =IF(Responses!Q2="","",IF(Responses!Q2="Tidak Benar",2,IF(Responses!Q2="Agak Benar",1,0))) -> 0 | R2: =IF(Responses!R2="","",IF(Responses!R2="Benar",2,IF(Responses!R2="Agak Benar",1,0))) -> 1 | S2: =IF(Responses!S2="","",IF(Responses!S2="Benar",2,IF(Responses!S2="Agak Benar",1,0))) -> 2 | T2: =IF(Responses!T2="","",IF(Responses!T2="Tidak Benar",2,IF(Responses!T2="Agak Benar",1,0))) -> 1 | U2: =IF(Responses!U2="","",IF(Responses!U2="Benar",2,IF(Responses!U2="Agak Benar",1,0))) -> 1 | V2: =IF(Responses!V2="","",IF(Responses!V2="Benar",2,IF(Responses!V2="Agak Benar",1,0))) -> 1 | W2: =IF(Responses!W2="","",IF(Responses!W2="Benar",2,IF(Responses!W2="Agak Benar",1,0))) -> 1 | X2: =IF(Responses!X2="","",IF(Responses!X2="Benar",2,IF(Responses!X2="Agak Benar",1,0))) -> 1 | Y2: =IF(Responses!Y2="","",IF(Responses!Y2="Benar",2,IF(Responses!Y2="Agak Benar",1,0))) -> 0 | Z2: =IF(Responses!Z2="","",IF(Responses!Z2="Benar",2,IF(Responses!Z2="Agak Benar",1,0))) -> 1 | AA2: =IF(Responses!AA2="","",IF(Responses!AA2="Tidak Benar",2,IF(Responses!AA2="Agak Benar",1,0))) -> 0 | AB2: =IF(Responses!AB2="","",IF(Responses!AB2="Benar",2,IF(Responses!AB2="Agak Benar",1,0))) -> 0 | AC2: =IF(Responses!AC2="","",IF(Responses!AC2="Benar",2,IF(Responses!AC2="Agak Benar",1,0))) -> 1 | AD2: =IF(Responses!AD2="","",IF(Responses!AD2="Benar",2,IF(Responses!AD2="Agak Benar",1,0))) -> 2 | AE2: =IF(Responses!AE2="","",IF(Responses!AE2="Tidak Benar",2,IF(Responses!AE2="Agak Benar",1,0))) -> 0 | AF2: =IF(A2="","",I2+N2+S2+V2+AD2) -> 9 | AG2: =IF(A2="","",K2+M2+R2+X2+AB2) -> 4 | AH2: =IF(A2="","",H2+P2+U2+AA2+AE2) -> 5 | AI2: =IF(A2="","",L2+Q2+T2+Y2+AC2) -> 3 | AJ2: =IF(A2="","",G2+J2+O2+W2+Z2) -> 7 | AK2: =IF(AF2="","",IF(AF2<=5,"Normal",IF(AF2=6,"Borderline","Abnormal"))) -> Abnormal | AL2: =IF(AG2="","",IF(AG2<=3,"Normal",IF(AG2=4,"Borderline","Abnormal"))) -> Borderline | AM2: =IF(AH2="","",IF(AH2<=5,"Normal",IF(AH2=6,"Borderline","Abnormal"))) -> Normal | AN2: =IF(AI2="","",IF(AI2<=3,"Normal",IF(AI2<=5,"Borderline","Abnormal"))) -> Normal | AO2: =IF(AJ2="","",IF(AJ2>=6,"Normal",IF(AJ2=5,"Borderline","Abnormal"))) -> Normal | AP2: =IF(A2="","",AF2+AG2+AH2+AI2) -> 21 | AQ2: =IF(A2="","",IF(AP2<=15,"Normal",IF(AP2<=19,"Borderline","Abnormal"))) -> Abnormal
A3: =Responses!A3 -> gbdE1PN | B3: =Responses!B3 -> XxRjYOd | C3: =Responses!C3 -> 46136.091 | D3: =Responses!D3 -> Habibah Putri Kawiswara | E3: =Responses!E3 -> XI-1 | F3: =Responses!F3 -> 11 | G3: =IF(Responses!G3="","",IF(Responses!G3="Benar",2,IF(Responses!G3="Agak Benar",1,0))) -> 2 | H3: =IF(Responses!H3="","",IF(Responses!H3="Benar",2,IF(Responses!H3="Agak Benar",1,0))) -> 1 | I3: =IF(Responses!I3="","",IF(Responses!I3="Benar",2,IF(Responses!I3="Agak Benar",1,0))) -> 2 | J3: =IF(Responses!J3="","",IF(Responses!J3="Benar",2,IF(Responses!J3="Agak Benar",1,0))) -> 1 | K3: =IF(Responses!K3="","",IF(Responses!K3="Benar",2,IF(Responses!K3="Agak Benar",1,0))) -> 1 | L3: =IF(Responses!L3="","",IF(Responses!L3="Benar",2,IF(Responses!L3="Agak Benar",1,0))) -> 2 | M3: =IF(Responses!M3="","",IF(Responses!M3="Tidak Benar",2,IF(Responses!M3="Agak Benar",1,0))) -> 0 | N3: =IF(Responses!N3="","",IF(Responses!N3="Benar",2,IF(Responses!N3="Agak Benar",1,0))) -> 1 | O3: =IF(Responses!O3="","",IF(Responses!O3="Benar",2,IF(Responses!O3="Agak Benar",1,0))) -> 1 | P3: =IF(Responses!P3="","",IF(Responses!P3="Benar",2,IF(Responses!P3="Agak Benar",1,0))) -> 2 | Q3: =IF(Responses!Q3="","",IF(Responses!Q3="Tidak Benar",2,IF(Responses!Q3="Agak Benar",1,0))) -> 0 | R3: =IF(Responses!R3="","",IF(Responses!R3="Benar",2,IF(Responses!R3="Agak Benar",1,0))) -> 0 | S3: =IF(Responses!S3="","",IF(Responses!S3="Benar",2,IF(Responses!S3="Agak Benar",1,0))) -> 1 | T3: =IF(Responses!T3="","",IF(Responses!T3="Tidak Benar",2,IF(Responses!T3="Agak Benar",1,0))) -> 2 | U3: =IF(Responses!U3="","",IF(Responses!U3="Benar",2,IF(Responses!U3="Agak Benar",1,0))) -> 1 | V3: =IF(Responses!V3="","",IF(Responses!V3="Benar",2,IF(Responses!V3="Agak Benar",1,0))) -> 2 | W3: =IF(Responses!W3="","",IF(Responses!W3="Benar",2,IF(Responses!W3="Agak Benar",1,0))) -> 2 | X3: =IF(Responses!X3="","",IF(Responses!X3="Benar",2,IF(Responses!X3="Agak Benar",1,0))) -> 0 | Y3: =IF(Responses!Y3="","",IF(Responses!Y3="Benar",2,IF(Responses!Y3="Agak Benar",1,0))) -> 0 | Z3: =IF(Responses!Z3="","",IF(Responses!Z3="Benar",2,IF(Responses!Z3="Agak Benar",1,0))) -> 2 | AA3: =IF(Responses!AA3="","",IF(Responses!AA3="Tidak Benar",2,IF(Responses!AA3="Agak Benar",1,0))) -> 1 | AB3: =IF(Responses!AB3="","",IF(Responses!AB3="Benar",2,IF(Responses!AB3="Agak Benar",1,0))) -> 0 | AC3: =IF(Responses!AC3="","",IF(Responses!AC3="Benar",2,IF(Responses!AC3="Agak Benar",1,0))) -> 0 | AD3: =IF(Responses!AD3="","",IF(Responses!AD3="Benar",2,IF(Responses!AD3="Agak Benar",1,0))) -> 1 | AE3: =IF(Responses!AE3="","",IF(Responses!AE3="Tidak Benar",2,IF(Responses!AE3="Agak Benar",1,0))) -> 2 | AF3: =IF(A3="","",I3+N3+S3+V3+AD3) -> 7 | AG3: =IF(A3="","",K3+M3+R3+X3+AB3) -> 1 | AH3: =IF(A3="","",H3+P3+U3+AA3+AE3) -> 7 | AI3: =IF(A3="","",L3+Q3+T3+Y3+AC3) -> 4 | AJ3: =IF(A3="","",G3+J3+O3+W3+Z3) -> 8 | AK3: =IF(AF3="","",IF(AF3<=5,"Normal",IF(AF3=6,"Borderline","Abnormal"))) -> Abnormal | AL3: =IF(AG3="","",IF(AG3<=3,"Normal",IF(AG3=4,"Borderline","Abnormal"))) -> Normal | AM3: =IF(AH3="","",IF(AH3<=5,"Normal",IF(AH3=6,"Borderline","Abnormal"))) -> Abnormal | AN3: =IF(AI3="","",IF(AI3<=3,"Normal",IF(AI3<=5,"Borderline","Abnormal"))) -> Borderline | AO3: =IF(AJ3="","",IF(AJ3>=6,"Normal",IF(AJ3=5,"Borderline","Abnormal"))) -> Normal | AP3: =IF(A3="","",AF3+AG3+AH3+AI3) -> 19 | AQ3: =IF(A3="","",IF(AP3<=15,"Normal",IF(AP3<=19,"Borderline","Abnormal"))) -> Borderline
A4: =Responses!A4 -> M1NW2Ol | B4: =Responses!B4 -> VL9r1r6 | C4: =Responses!C4 -> 46136.092 | D4: =Responses!D4 -> Julian | E4: =Responses!E4 -> XI-1 | F4: =Responses!F4 -> 16 | G4: =IF(Responses!G4="","",IF(Responses!G4="Benar",2,IF(Responses!G4="Agak Benar",1,0))) -> 2 | H4: =IF(Responses!H4="","",IF(Responses!H4="Benar",2,IF(Responses!H4="Agak Benar",1,0))) -> 2 | I4: =IF(Responses!I4="","",IF(Responses!I4="Benar",2,IF(Responses!I4="Agak Benar",1,0))) -> 0 | J4: =IF(Responses!J4="","",IF(Responses!J4="Benar",2,IF(Responses!J4="Agak Benar",1,0))) -> 1 | K4: =IF(Responses!K4="","",IF(Responses!K4="Benar",2,IF(Responses!K4="Agak Benar",1,0))) -> 0 | L4: =IF(Responses!L4="","",IF(Responses!L4="Benar",2,IF(Responses!L4="Agak Benar",1,0))) -> 2 | M4: =IF(Responses!M4="","",IF(Responses!M4="Tidak Benar",2,IF(Responses!M4="Agak Benar",1,0))) -> 2 | N4: =IF(Responses!N4="","",IF(Responses!N4="Benar",2,IF(Responses!N4="Agak Benar",1,0))) -> 0 | O4: =IF(Responses!O4="","",IF(Responses!O4="Benar",2,IF(Responses!O4="Agak Benar",1,0))) -> 2 | P4: =IF(Responses!P4="","",IF(Responses!P4="Benar",2,IF(Responses!P4="Agak Benar",1,0))) -> 0 | Q4: =IF(Responses!Q4="","",IF(Responses!Q4="Tidak Benar",2,IF(Responses!Q4="Agak Benar",1,0))) -> 0 | R4: =IF(Responses!R4="","",IF(Responses!R4="Benar",2,IF(Responses!R4="Agak Benar",1,0))) -> 0 | S4: =IF(Responses!S4="","",IF(Responses!S4="Benar",2,IF(Responses!S4="Agak Benar",1,0))) -> 0 | T4: =IF(Responses!T4="","",IF(Responses!T4="Tidak Benar",2,IF(Responses!T4="Agak Benar",1,0))) -> 1 | U4: =IF(Responses!U4="","",IF(Responses!U4="Benar",2,IF(Responses!U4="Agak Benar",1,0))) -> 0 | V4: =IF(Responses!V4="","",IF(Responses!V4="Benar",2,IF(Responses!V4="Agak Benar",1,0))) -> 0 | W4: =IF(Responses!W4="","",IF(Responses!W4="Benar",2,IF(Responses!W4="Agak Benar",1,0))) -> 2 | X4: =IF(Responses!X4="","",IF(Responses!X4="Benar",2,IF(Responses!X4="Agak Benar",1,0))) -> 0 | Y4: =IF(Responses!Y4="","",IF(Responses!Y4="Benar",2,IF(Responses!Y4="Agak Benar",1,0))) -> 0 | Z4: =IF(Responses!Z4="","",IF(Responses!Z4="Benar",2,IF(Responses!Z4="Agak Benar",1,0))) -> 1 | AA4: =IF(Responses!AA4="","",IF(Responses!AA4="Tidak Benar",2,IF(Responses!AA4="Agak Benar",1,0))) -> 0 | AB4: =IF(Responses!AB4="","",IF(Responses!AB4="Benar",2,IF(Responses!AB4="Agak Benar",1,0))) -> 0 | AC4: =IF(Responses!AC4="","",IF(Responses!AC4="Benar",2,IF(Responses!AC4="Agak Benar",1,0))) -> 0 | AD4: =IF(Responses!AD4="","",IF(Responses!AD4="Benar",2,IF(Responses!AD4="Agak Benar",1,0))) -> 0 | AE4: =IF(Responses!AE4="","",IF(Responses!AE4="Tidak Benar",2,IF(Responses!AE4="Agak Benar",1,0))) -> 1 | AF4: =IF(A4="","",I4+N4+S4+V4+AD4) -> 0 | AG4: =IF(A4="","",K4+M4+R4+X4+AB4) -> 2 | AH4: =IF(A4="","",H4+P4+U4+AA4+AE4) -> 3 | AI4: =IF(A4="","",L4+Q4+T4+Y4+AC4) -> 3 | AJ4: =IF(A4="","",G4+J4+O4+W4+Z4) -> 8 | AK4: =IF(AF4="","",IF(AF4<=5,"Normal",IF(AF4=6,"Borderline","Abnormal"))) -> Normal | AL4: =IF(AG4="","",IF(AG4<=3,"Normal",IF(AG4=4,"Borderline","Abnormal"))) -> Normal | AM4: =IF(AH4="","",IF(AH4<=5,"Normal",IF(AH4=6,"Borderline","Abnormal"))) -> Normal | AN4: =IF(AI4="","",IF(AI4<=3,"Normal",IF(AI4<=5,"Borderline","Abnormal"))) -> Normal | AO4: =IF(AJ4="","",IF(AJ4>=6,"Normal",IF(AJ4=5,"Borderline","Abnormal"))) -> Normal | AP4: =IF(A4="","",AF4+AG4+AH4+AI4) -> 8 | AQ4: =IF(A4="","",IF(AP4<=15,"Normal",IF(AP4<=19,"Borderline","Abnormal"))) -> Normal
A5: =Responses!A5 -> 9N98jAV | B5: =Responses!B5 -> RGZObRK | C5: =Responses!C5 -> 46136.092 | D5: =Responses!D5 -> Qori Ilyasa Fariduddin Purwadi | E5: =Responses!E5 -> XI-1 | F5: =Responses!F5 -> 17 | G5: =IF(Responses!G5="","",IF(Responses!G5="Benar",2,IF(Responses!G5="Agak Benar",1,0))) -> 1 | H5: =IF(Responses!H5="","",IF(Responses!H5="Benar",2,IF(Responses!H5="Agak Benar",1,0))) -> 0 | I5: =IF(Responses!I5="","",IF(Responses!I5="Benar",2,IF(Responses!I5="Agak Benar",1,0))) -> 2 | J5: =IF(Responses!J5="","",IF(Responses!J5="Benar",2,IF(Responses!J5="Agak Benar",1,0))) -> 2 | K5: =IF(Responses!K5="","",IF(Responses!K5="Benar",2,IF(Responses!K5="Agak Benar",1,0))) -> 1 | L5: =IF(Responses!L5="","",IF(Responses!L5="Benar",2,IF(Responses!L5="Agak Benar",1,0))) -> 1 | M5: =IF(Responses!M5="","",IF(Responses!M5="Tidak Benar",2,IF(Responses!M5="Agak Benar",1,0))) -> 1 | N5: =IF(Responses!N5="","",IF(Responses!N5="Benar",2,IF(Responses!N5="Agak Benar",1,0))) -> 2 | O5: =IF(Responses!O5="","",IF(Responses!O5="Benar",2,IF(Responses!O5="Agak Benar",1,0))) -> 2 | P5: =IF(Responses!P5="","",IF(Responses!P5="Benar",2,IF(Responses!P5="Agak Benar",1,0))) -> 2 | Q5: =IF(Responses!Q5="","",IF(Responses!Q5="Tidak Benar",2,IF(Responses!Q5="Agak Benar",1,0))) -> 1 | R5: =IF(Responses!R5="","",IF(Responses!R5="Benar",2,IF(Responses!R5="Agak Benar",1,0))) -> 1 | S5: =IF(Responses!S5="","",IF(Responses!S5="Benar",2,IF(Responses!S5="Agak Benar",1,0))) -> 2 | T5: =IF(Responses!T5="","",IF(Responses!T5="Tidak Benar",2,IF(Responses!T5="Agak Benar",1,0))) -> 2 | U5: =IF(Responses!U5="","",IF(Responses!U5="Benar",2,IF(Responses!U5="Agak Benar",1,0))) -> 2 | V5: =IF(Responses!V5="","",IF(Responses!V5="Benar",2,IF(Responses!V5="Agak Benar",1,0))) -> 1 | W5: =IF(Responses!W5="","",IF(Responses!W5="Benar",2,IF(Responses!W5="Agak Benar",1,0))) -> 2 | X5: =IF(Responses!X5="","",IF(Responses!X5="Benar",2,IF(Responses!X5="Agak Benar",1,0))) -> 1 | Y5: =IF(Responses!Y5="","",IF(Responses!Y5="Benar",2,IF(Responses!Y5="Agak Benar",1,0))) -> 1 | Z5: =IF(Responses!Z5="","",IF(Responses!Z5="Benar",2,IF(Responses!Z5="Agak Benar",1,0))) -> 2 | AA5: =IF(Responses!AA5="","",IF(Responses!AA5="Tidak Benar",2,IF(Responses!AA5="Agak Benar",1,0))) -> 0 | AB5: =IF(Responses!AB5="","",IF(Responses!AB5="Benar",2,IF(Responses!AB5="Agak Benar",1,0))) -> 0 | AC5: =IF(Responses!AC5="","",IF(Responses!AC5="Benar",2,IF(Responses!AC5="Agak Benar",1,0))) -> 2 | AD5: =IF(Responses!AD5="","",IF(Responses!AD5="Benar",2,IF(Responses!AD5="Agak Benar",1,0))) -> 2 | AE5: =IF(Responses!AE5="","",IF(Responses!AE5="Tidak Benar",2,IF(Responses!AE5="Agak Benar",1,0))) -> 2 | AF5: =IF(A5="","",I5+N5+S5+V5+AD5) -> 9 | AG5: =IF(A5="","",K5+M5+R5+X5+AB5) -> 4 | AH5: =IF(A5="","",H5+P5+U5+AA5+AE5) -> 6 | AI5: =IF(A5="","",L5+Q5+T5+Y5+AC5) -> 7 | AJ5: =IF(A5="","",G5+J5+O5+W5+Z5) -> 9 | AK5: =IF(AF5="","",IF(AF5<=5,"Normal",IF(AF5=6,"Borderline","Abnormal"))) -> Abnormal | AL5: =IF(AG5="","",IF(AG5<=3,"Normal",IF(AG5=4,"Borderline","Abnormal"))) -> Borderline | AM5: =IF(AH5="","",IF(AH5<=5,"Normal",IF(AH5=6,"Borderline","Abnormal"))) -> Borderline | AN5: =IF(AI5="","",IF(AI5<=3,"Normal",IF(AI5<=5,"Borderline","Abnormal"))) -> Abnormal | AO5: =IF(AJ5="","",IF(AJ5>=6,"Normal",IF(AJ5=5,"Borderline","Abnormal"))) -> Normal | AP5: =IF(A5="","",AF5+AG5+AH5+AI5) -> 26 | AQ5: =IF(A5="","",IF(AP5<=15,"Normal",IF(AP5<=19,"Borderline","Abnormal"))) -> Abnormal
A6: =Responses!A6 -> Eqd2RJ2 | B6: =Responses!B6 -> EkBpN2L | C6: =Responses!C6 -> 46136.093 | D6: =Responses!D6 -> Kirana Annisa Noegroho | E6: =Responses!E6 -> XI-1 | F6: =Responses!F6 -> 16 | G6: =IF(Responses!G6="","",IF(Responses!G6="Benar",2,IF(Responses!G6="Agak Benar",1,0))) -> 2 | H6: =IF(Responses!H6="","",IF(Responses!H6="Benar",2,IF(Responses!H6="Agak Benar",1,0))) -> 2 | I6: =IF(Responses!I6="","",IF(Responses!I6="Benar",2,IF(Responses!I6="Agak Benar",1,0))) -> 0 | J6: =IF(Responses!J6="","",IF(Responses!J6="Benar",2,IF(Responses!J6="Agak Benar",1,0))) -> 1 | K6: =IF(Responses!K6="","",IF(Responses!K6="Benar",2,IF(Responses!K6="Agak Benar",1,0))) -> 0 | L6: =IF(Responses!L6="","",IF(Responses!L6="Benar",2,IF(Responses!L6="Agak Benar",1,0))) -> 0 | M6: =IF(Responses!M6="","",IF(Responses!M6="Tidak Benar",2,IF(Responses!M6="Agak Benar",1,0))) -> 1 | N6: =IF(Responses!N6="","",IF(Responses!N6="Benar",2,IF(Responses!N6="Agak Benar",1,0))) -> 1 | O6: =IF(Responses!O6="","",IF(Responses!O6="Benar",2,IF(Responses!O6="Agak Benar",1,0))) -> 1 | P6: =IF(Responses!P6="","",IF(Responses!P6="Benar",2,IF(Responses!P6="Agak Benar",1,0))) -> 2 | Q6: =IF(Responses!Q6="","",IF(Responses!Q6="Tidak Benar",2,IF(Responses!Q6="Agak Benar",1,0))) -> 0 | R6: =IF(Responses!R6="","",IF(Responses!R6="Benar",2,IF(Responses!R6="Agak Benar",1,0))) -> 0 | S6: =IF(Responses!S6="","",IF(Responses!S6="Benar",2,IF(Responses!S6="Agak Benar",1,0))) -> 0 | T6: =IF(Responses!T6="","",IF(Responses!T6="Tidak Benar",2,IF(Responses!T6="Agak Benar",1,0))) -> 0 | U6: =IF(Responses!U6="","",IF(Responses!U6="Benar",2,IF(Responses!U6="Agak Benar",1,0))) -> 0 | V6: =IF(Responses!V6="","",IF(Responses!V6="Benar",2,IF(Responses!V6="Agak Benar",1,0))) -> 1 | W6: =IF(Responses!W6="","",IF(Responses!W6="Benar",2,IF(Responses!W6="Agak Benar",1,0))) -> 1 | X6: =IF(Responses!X6="","",IF(Responses!X6="Benar",2,IF(Responses!X6="Agak Benar",1,0))) -> 0 | Y6: =IF(Responses!Y6="","",IF(Responses!Y6="Benar",2,IF(Responses!Y6="Agak Benar",1,0))) -> 0 | Z6: =IF(Responses!Z6="","",IF(Responses!Z6="Benar",2,IF(Responses!Z6="Agak Benar",1,0))) -> 1 | AA6: =IF(Responses!AA6="","",IF(Responses!AA6="Tidak Benar",2,IF(Responses!AA6="Agak Benar",1,0))) -> 1 | AB6: =IF(Responses!AB6="","",IF(Responses!AB6="Benar",2,IF(Responses!AB6="Agak Benar",1,0))) -> 0 | AC6: =IF(Responses!AC6="","",IF(Responses!AC6="Benar",2,IF(Responses!AC6="Agak Benar",1,0))) -> 0 | AD6: =IF(Responses!AD6="","",IF(Responses!AD6="Benar",2,IF(Responses!AD6="Agak Benar",1,0))) -> 1 | AE6: =IF(Responses!AE6="","",IF(Responses!AE6="Tidak Benar",2,IF(Responses!AE6="Agak Benar",1,0))) -> 0 | AF6: =IF(A6="","",I6+N6+S6+V6+AD6) -> 3 | AG6: =IF(A6="","",K6+M6+R6+X6+AB6) -> 1 | AH6: =IF(A6="","",H6+P6+U6+AA6+AE6) -> 5 | AI6: =IF(A6="","",L6+Q6+T6+Y6+AC6) -> 0 | AJ6: =IF(A6="","",G6+J6+O6+W6+Z6) -> 6 | AK6: =IF(AF6="","",IF(AF6<=5,"Normal",IF(AF6=6,"Borderline","Abnormal"))) -> Normal | AL6: =IF(AG6="","",IF(AG6<=3,"Normal",IF(AG6=4,"Borderline","Abnormal"))) -> Normal | AM6: =IF(AH6="","",IF(AH6<=5,"Normal",IF(AH6=6,"Borderline","Abnormal"))) -> Normal | AN6: =IF(AI6="","",IF(AI6<=3,"Normal",IF(AI6<=5,"Borderline","Abnormal"))) -> Normal | AO6: =IF(AJ6="","",IF(AJ6>=6,"Normal",IF(AJ6=5,"Borderline","Abnormal"))) -> Normal | AP6: =IF(A6="","",AF6+AG6+AH6+AI6) -> 9 | AQ6: =IF(A6="","",IF(AP6<=15,"Normal",IF(AP6<=19,"Borderline","Abnormal"))) -> Normal
A7: =Responses!A7 -> BEdrr21 | B7: =Responses!B7 -> Np4zdeW | C7: =Responses!C7 -> 46136.093 | D7: =Responses!D7 -> Raffarel Jozka Dafiq Prihantara | E7: =Responses!E7 -> XI-1 | F7: =Responses!F7 -> 16 | G7: =IF(Responses!G7="","",IF(Responses!G7="Benar",2,IF(Responses!G7="Agak Benar",1,0))) -> 2 | H7: =IF(Responses!H7="","",IF(Responses!H7="Benar",2,IF(Responses!H7="Agak Benar",1,0))) -> 2 | I7: =IF(Responses!I7="","",IF(Responses!I7="Benar",2,IF(Responses!I7="Agak Benar",1,0))) -> 0 | J7: =IF(Responses!J7="","",IF(Responses!J7="Benar",2,IF(Responses!J7="Agak Benar",1,0))) -> 2 | K7: =IF(Responses!K7="","",IF(Responses!K7="Benar",2,IF(Responses!K7="Agak Benar",1,0))) -> 1 | L7: =IF(Responses!L7="","",IF(Responses!L7="Benar",2,IF(Responses!L7="Agak Benar",1,0))) -> 0 | M7: =IF(Responses!M7="","",IF(Responses!M7="Tidak Benar",2,IF(Responses!M7="Agak Benar",1,0))) -> 2 | N7: =IF(Responses!N7="","",IF(Responses!N7="Benar",2,IF(Responses!N7="Agak Benar",1,0))) -> 0 | O7: =IF(Responses!O7="","",IF(Responses!O7="Benar",2,IF(Responses!O7="Agak Benar",1,0))) -> 2 | P7: =IF(Responses!P7="","",IF(Responses!P7="Benar",2,IF(Responses!P7="Agak Benar",1,0))) -> 1 | Q7: =IF(Responses!Q7="","",IF(Responses!Q7="Tidak Benar",2,IF(Responses!Q7="Agak Benar",1,0))) -> 0 | R7: =IF(Responses!R7="","",IF(Responses!R7="Benar",2,IF(Responses!R7="Agak Benar",1,0))) -> 0 | S7: =IF(Responses!S7="","",IF(Responses!S7="Benar",2,IF(Responses!S7="Agak Benar",1,0))) -> 0 | T7: =IF(Responses!T7="","",IF(Responses!T7="Tidak Benar",2,IF(Responses!T7="Agak Benar",1,0))) -> 0 | U7: =IF(Responses!U7="","",IF(Responses!U7="Benar",2,IF(Responses!U7="Agak Benar",1,0))) -> 1 | V7: =IF(Responses!V7="","",IF(Responses!V7="Benar",2,IF(Responses!V7="Agak Benar",1,0))) -> 1 | W7: =IF(Responses!W7="","",IF(Responses!W7="Benar",2,IF(Responses!W7="Agak Benar",1,0))) -> 2 | X7: =IF(Responses!X7="","",IF(Responses!X7="Benar",2,IF(Responses!X7="Agak Benar",1,0))) -> 0 | Y7: =IF(Responses!Y7="","",IF(Responses!Y7="Benar",2,IF(Responses!Y7="Agak Benar",1,0))) -> 0 | Z7: =IF(Responses!Z7="","",IF(Responses!Z7="Benar",2,IF(Responses!Z7="Agak Benar",1,0))) -> 2 | AA7: =IF(Responses!AA7="","",IF(Responses!AA7="Tidak Benar",2,IF(Responses!AA7="Agak Benar",1,0))) -> 0 | AB7: =IF(Responses!AB7="","",IF(Responses!AB7="Benar",2,IF(Responses!AB7="Agak Benar",1,0))) -> 0 | AC7: =IF(Responses!AC7="","",IF(Responses!AC7="Benar",2,IF(Responses!AC7="Agak Benar",1,0))) -> 2 | AD7: =IF(Responses!AD7="","",IF(Responses!AD7="Benar",2,IF(Responses!AD7="Agak Benar",1,0))) -> 0 | AE7: =IF(Responses!AE7="","",IF(Responses!AE7="Tidak Benar",2,IF(Responses!AE7="Agak Benar",1,0))) -> 0 | AF7: =IF(A7="","",I7+N7+S7+V7+AD7) -> 1 | AG7: =IF(A7="","",K7+M7+R7+X7+AB7) -> 3 | AH7: =IF(A7="","",H7+P7+U7+AA7+AE7) -> 4 | AI7: =IF(A7="","",L7+Q7+T7+Y7+AC7) -> 2 | AJ7: =IF(A7="","",G7+J7+O7+W7+Z7) -> 10 | AK7: =IF(AF7="","",IF(AF7<=5,"Normal",IF(AF7=6,"Borderline","Abnormal"))) -> Normal | AL7: =IF(AG7="","",IF(AG7<=3,"Normal",IF(AG7=4,"Borderline","Abnormal"))) -> Normal | AM7: =IF(AH7="","",IF(AH7<=5,"Normal",IF(AH7=6,"Borderline","Abnormal"))) -> Normal | AN7: =IF(AI7="","",IF(AI7<=3,"Normal",IF(AI7<=5,"Borderline","Abnormal"))) -> Normal | AO7: =IF(AJ7="","",IF(AJ7>=6,"Normal",IF(AJ7=5,"Borderline","Abnormal"))) -> Normal | AP7: =IF(A7="","",AF7+AG7+AH7+AI7) -> 10 | AQ7: =IF(A7="","",IF(AP7<=15,"Normal",IF(AP7<=19,"Borderline","Abnormal"))) -> Normal
A8: =Responses!A8 -> M1NW06g | B8: =Responses!B8 -> vG0Rzk0 | C8: =Responses!C8 -> 46136.093 | D8: =Responses!D8 -> Salwa Nafisatul Khoerun Nisa | E8: =Responses!E8 -> XI-1 | F8: =Responses!F8 -> 17 | G8: =IF(Responses!G8="","",IF(Responses!G8="Benar",2,IF(Responses!G8="Agak Benar",1,0))) -> 2 | H8: =IF(Responses!H8="","",IF(Responses!H8="Benar",2,IF(Responses!H8="Agak Benar",1,0))) -> 1 | I8: =IF(Responses!I8="","",IF(Responses!I8="Benar",2,IF(Responses!I8="Agak Benar",1,0))) -> 2 | J8: =IF(Responses!J8="","",IF(Responses!J8="Benar",2,IF(Responses!J8="Agak Benar",1,0))) -> 2 | K8: =IF(Responses!K8="","",IF(Responses!K8="Benar",2,IF(Responses!K8="Agak Benar",1,0))) -> 0 | L8: =IF(Responses!L8="","",IF(Responses!L8="Benar",2,IF(Responses!L8="Agak Benar",1,0))) -> 2 | M8: =IF(Responses!M8="","",IF(Responses!M8="Tidak Benar",2,IF(Responses!M8="Agak Benar",1,0))) -> 0 | N8: =IF(Responses!N8="","",IF(Responses!N8="Benar",2,IF(Responses!N8="Agak Benar",1,0))) -> 2 | O8: =IF(Responses!O8="","",IF(Responses!O8="Benar",2,IF(Responses!O8="Agak Benar",1,0))) -> 2 | P8: =IF(Responses!P8="","",IF(Responses!P8="Benar",2,IF(Responses!P8="Agak Benar",1,0))) -> 2 | Q8: =IF(Responses!Q8="","",IF(Responses!Q8="Tidak Benar",2,IF(Responses!Q8="Agak Benar",1,0))) -> 0 | R8: =IF(Responses!R8="","",IF(Responses!R8="Benar",2,IF(Responses!R8="Agak Benar",1,0))) -> 0 | S8: =IF(Responses!S8="","",IF(Responses!S8="Benar",2,IF(Responses!S8="Agak Benar",1,0))) -> 1 | T8: =IF(Responses!T8="","",IF(Responses!T8="Tidak Benar",2,IF(Responses!T8="Agak Benar",1,0))) -> 0 | U8: =IF(Responses!U8="","",IF(Responses!U8="Benar",2,IF(Responses!U8="Agak Benar",1,0))) -> 1 | V8: =IF(Responses!V8="","",IF(Responses!V8="Benar",2,IF(Responses!V8="Agak Benar",1,0))) -> 2 | W8: =IF(Responses!W8="","",IF(Responses!W8="Benar",2,IF(Responses!W8="Agak Benar",1,0))) -> 2 | X8: =IF(Responses!X8="","",IF(Responses!X8="Benar",2,IF(Responses!X8="Agak Benar",1,0))) -> 0 | Y8: =IF(Responses!Y8="","",IF(Responses!Y8="Benar",2,IF(Responses!Y8="Agak Benar",1,0))) -> 0 | Z8: =IF(Responses!Z8="","",IF(Responses!Z8="Benar",2,IF(Responses!Z8="Agak Benar",1,0))) -> 2 | AA8: =IF(Responses!AA8="","",IF(Responses!AA8="Tidak Benar",2,IF(Responses!AA8="Agak Benar",1,0))) -> 0 | AB8: =IF(Responses!AB8="","",IF(Responses!AB8="Benar",2,IF(Responses!AB8="Agak Benar",1,0))) -> 0 | AC8: =IF(Responses!AC8="","",IF(Responses!AC8="Benar",2,IF(Responses!AC8="Agak Benar",1,0))) -> 0 | AD8: =IF(Responses!AD8="","",IF(Responses!AD8="Benar",2,IF(Responses!AD8="Agak Benar",1,0))) -> 2 | AE8: =IF(Responses!AE8="","",IF(Responses!AE8="Tidak Benar",2,IF(Responses!AE8="Agak Benar",1,0))) -> 0 | AF8: =IF(A8="","",I8+N8+S8+V8+AD8) -> 9 | AG8: =IF(A8="","",K8+M8+R8+X8+AB8) -> 0 | AH8: =IF(A8="","",H8+P8+U8+AA8+AE8) -> 4 | AI8: =IF(A8="","",L8+Q8+T8+Y8+AC8) -> 2 | AJ8: =IF(A8="","",G8+J8+O8+W8+Z8) -> 10 | AK8: =IF(AF8="","",IF(AF8<=5,"Normal",IF(AF8=6,"Borderline","Abnormal"))) -> Abnormal | AL8: =IF(AG8="","",IF(AG8<=3,"Normal",IF(AG8=4,"Borderline","Abnormal"))) -> Normal | AM8: =IF(AH8="","",IF(AH8<=5,"Normal",IF(AH8=6,"Borderline","Abnormal"))) -> Normal | AN8: =IF(AI8="","",IF(AI8<=3,"Normal",IF(AI8<=5,"Borderline","Abnormal"))) -> Normal | AO8: =IF(AJ8="","",IF(AJ8>=6,"Normal",IF(AJ8=5,"Borderline","Abnormal"))) -> Normal | AP8: =IF(A8="","",AF8+AG8+AH8+AI8) -> 15 | AQ8: =IF(A8="","",IF(AP8<=15,"Normal",IF(AP8<=19,"Borderline","Abnormal"))) -> Normal
A9: =Responses!A9 -> zEykPxa | B9: =Responses!B9 -> VL9rq96 | C9: =Responses!C9 -> 46136.093 | D9: =Responses!D9 -> Najwa Alya Puteri | E9: =Responses!E9 -> XI-1 | F9: =Responses!F9 -> 17 | G9: =IF(Responses!G9="","",IF(Responses!G9="Benar",2,IF(Responses!G9="Agak Benar",1,0))) -> 2 | H9: =IF(Responses!H9="","",IF(Responses!H9="Benar",2,IF(Responses!H9="Agak Benar",1,0))) -> 0 | I9: =IF(Responses!I9="","",IF(Responses!I9="Benar",2,IF(Responses!I9="Agak Benar",1,0))) -> 2 | J9: =IF(Responses!J9="","",IF(Responses!J9="Benar",2,IF(Responses!J9="Agak Benar",1,0))) -> 1 | K9: =IF(Responses!K9="","",IF(Responses!K9="Benar",2,IF(Responses!K9="Agak Benar",1,0))) -> 1 | L9: =IF(Responses!L9="","",IF(Responses!L9="Benar",2,IF(Responses!L9="Agak Benar",1,0))) -> 1 | M9: =IF(Responses!M9="","",IF(Responses!M9="Tidak Benar",2,IF(Responses!M9="Agak Benar",1,0))) -> 1 | N9: =IF(Responses!N9="","",IF(Responses!N9="Benar",2,IF(Responses!N9="Agak Benar",1,0))) -> 1 | O9: =IF(Responses!O9="","",IF(Responses!O9="Benar",2,IF(Responses!O9="Agak Benar",1,0))) -> 2 | P9: =IF(Responses!P9="","",IF(Responses!P9="Benar",2,IF(Responses!P9="Agak Benar",1,0))) -> 0 | Q9: =IF(Responses!Q9="","",IF(Responses!Q9="Tidak Benar",2,IF(Responses!Q9="Agak Benar",1,0))) -> 0 | R9: =IF(Responses!R9="","",IF(Responses!R9="Benar",2,IF(Responses!R9="Agak Benar",1,0))) -> 1 | S9: =IF(Responses!S9="","",IF(Responses!S9="Benar",2,IF(Responses!S9="Agak Benar",1,0))) -> 1 | T9: =IF(Responses!T9="","",IF(Responses!T9="Tidak Benar",2,IF(Responses!T9="Agak Benar",1,0))) -> 2 | U9: =IF(Responses!U9="","",IF(Responses!U9="Benar",2,IF(Responses!U9="Agak Benar",1,0))) -> 0 | V9: =IF(Responses!V9="","",IF(Responses!V9="Benar",2,IF(Responses!V9="Agak Benar",1,0))) -> 2 | W9: =IF(Responses!W9="","",IF(Responses!W9="Benar",2,IF(Responses!W9="Agak Benar",1,0))) -> 1 | X9: =IF(Responses!X9="","",IF(Responses!X9="Benar",2,IF(Responses!X9="Agak Benar",1,0))) -> 1 | Y9: =IF(Responses!Y9="","",IF(Responses!Y9="Benar",2,IF(Responses!Y9="Agak Benar",1,0))) -> 2 | Z9: =IF(Responses!Z9="","",IF(Responses!Z9="Benar",2,IF(Responses!Z9="Agak Benar",1,0))) -> 2 | AA9: =IF(Responses!AA9="","",IF(Responses!AA9="Tidak Benar",2,IF(Responses!AA9="Agak Benar",1,0))) -> 0 | AB9: =IF(Responses!AB9="","",IF(Responses!AB9="Benar",2,IF(Responses!AB9="Agak Benar",1,0))) -> 0 | AC9: =IF(Responses!AC9="","",IF(Responses!AC9="Benar",2,IF(Responses!AC9="Agak Benar",1,0))) -> 1 | AD9: =IF(Responses!AD9="","",IF(Responses!AD9="Benar",2,IF(Responses!AD9="Agak Benar",1,0))) -> 1 | AE9: =IF(Responses!AE9="","",IF(Responses!AE9="Tidak Benar",2,IF(Responses!AE9="Agak Benar",1,0))) -> 1 | AF9: =IF(A9="","",I9+N9+S9+V9+AD9) -> 7 | AG9: =IF(A9="","",K9+M9+R9+X9+AB9) -> 4 | AH9: =IF(A9="","",H9+P9+U9+AA9+AE9) -> 1 | AI9: =IF(A9="","",L9+Q9+T9+Y9+AC9) -> 6 | AJ9: =IF(A9="","",G9+J9+O9+W9+Z9) -> 8 | AK9: =IF(AF9="","",IF(AF9<=5,"Normal",IF(AF9=6,"Borderline","Abnormal"))) -> Abnormal | AL9: =IF(AG9="","",IF(AG9<=3,"Normal",IF(AG9=4,"Borderline","Abnormal"))) -> Borderline | AM9: =IF(AH9="","",IF(AH9<=5,"Normal",IF(AH9=6,"Borderline","Abnormal"))) -> Normal | AN9: =IF(AI9="","",IF(AI9<=3,"Normal",IF(AI9<=5,"Borderline","Abnormal"))) -> Abnormal | AO9: =IF(AJ9="","",IF(AJ9>=6,"Normal",IF(AJ9=5,"Borderline","Abnormal"))) -> Normal | AP9: =IF(A9="","",AF9+AG9+AH9+AI9) -> 18 | AQ9: =IF(A9="","",IF(AP9<=15,"Normal",IF(AP9<=19,"Borderline","Abnormal"))) -> Borderline
A10: =Responses!A10 -> BEdrMd7 | B10: =Responses!B10 -> Mer0P6k | C10: =Responses!C10 -> 46136.093 | D10: =Responses!D10 -> Syarifah Lutfia Varisha | E10: =Responses!E10 -> XI-1 | F10: =Responses!F10 -> 17 | G10: =IF(Responses!G10="","",IF(Responses!G10="Benar",2,IF(Responses!G10="Agak Benar",1,0))) -> 2 | H10: =IF(Responses!H10="","",IF(Responses!H10="Benar",2,IF(Responses!H10="Agak Benar",1,0))) -> 2 | I10: =IF(Responses!I10="","",IF(Responses!I10="Benar",2,IF(Responses!I10="Agak Benar",1,0))) -> 1 | J10: =IF(Responses!J10="","",IF(Responses!J10="Benar",2,IF(Responses!J10="Agak Benar",1,0))) -> 1 | K10: =IF(Responses!K10="","",IF(Responses!K10="Benar",2,IF(Responses!K10="Agak Benar",1,0))) -> 1 | L10: =IF(Responses!L10="","",IF(Responses!L10="Benar",2,IF(Responses!L10="Agak Benar",1,0))) -> 0 | M10: =IF(Responses!M10="","",IF(Responses!M10="Tidak Benar",2,IF(Responses!M10="Agak Benar",1,0))) -> 0 | N10: =IF(Responses!N10="","",IF(Responses!N10="Benar",2,IF(Responses!N10="Agak Benar",1,0))) -> 2 | O10: =IF(Responses!O10="","",IF(Responses!O10="Benar",2,IF(Responses!O10="Agak Benar",1,0))) -> 2 | P10: =IF(Responses!P10="","",IF(Responses!P10="Benar",2,IF(Responses!P10="Agak Benar",1,0))) -> 2 | Q10: =IF(Responses!Q10="","",IF(Responses!Q10="Tidak Benar",2,IF(Responses!Q10="Agak Benar",1,0))) -> 0 | R10: =IF(Responses!R10="","",IF(Responses!R10="Benar",2,IF(Responses!R10="Agak Benar",1,0))) -> 0 | S10: =IF(Responses!S10="","",IF(Responses!S10="Benar",2,IF(Responses!S10="Agak Benar",1,0))) -> 1 | T10: =IF(Responses!T10="","",IF(Responses!T10="Tidak Benar",2,IF(Responses!T10="Agak Benar",1,0))) -> 0 | U10: =IF(Responses!U10="","",IF(Responses!U10="Benar",2,IF(Responses!U10="Agak Benar",1,0))) -> 1 | V10: =IF(Responses!V10="","",IF(Responses!V10="Benar",2,IF(Responses!V10="Agak Benar",1,0))) -> 1 | W10: =IF(Responses!W10="","",IF(Responses!W10="Benar",2,IF(Responses!W10="Agak Benar",1,0))) -> 2 | X10: =IF(Responses!X10="","",IF(Responses!X10="Benar",2,IF(Responses!X10="Agak Benar",1,0))) -> 1 | Y10: =IF(Responses!Y10="","",IF(Responses!Y10="Benar",2,IF(Responses!Y10="Agak Benar",1,0))) -> 0 | Z10: =IF(Responses!Z10="","",IF(Responses!Z10="Benar",2,IF(Responses!Z10="Agak Benar",1,0))) -> 2 | AA10: =IF(Responses!AA10="","",IF(Responses!AA10="Tidak Benar",2,IF(Responses!AA10="Agak Benar",1,0))) -> 0 | AB10: =IF(Responses!AB10="","",IF(Responses!AB10="Benar",2,IF(Responses!AB10="Agak Benar",1,0))) -> 0 | AC10: =IF(Responses!AC10="","",IF(Responses!AC10="Benar",2,IF(Responses!AC10="Agak Benar",1,0))) -> 0 | AD10: =IF(Responses!AD10="","",IF(Responses!AD10="Benar",2,IF(Responses!AD10="Agak Benar",1,0))) -> 1 | AE10: =IF(Responses!AE10="","",IF(Responses!AE10="Tidak Benar",2,IF(Responses!AE10="Agak Benar",1,0))) -> 1 | AF10: =IF(A10="","",I10+N10+S10+V10+AD10) -> 6 | AG10: =IF(A10="","",K10+M10+R10+X10+AB10) -> 2 | AH10: =IF(A10="","",H10+P10+U10+AA10+AE10) -> 6 | AI10: =IF(A10="","",L10+Q10+T10+Y10+AC10) -> 0 | AJ10: =IF(A10="","",G10+J10+O10+W10+Z10) -> 9 | AK10: =IF(AF10="","",IF(AF10<=5,"Normal",IF(AF10=6,"Borderline","Abnormal"))) -> Borderline | AL10: =IF(AG10="","",IF(AG10<=3,"Normal",IF(AG10=4,"Borderline","Abnormal"))) -> Normal | AM10: =IF(AH10="","",IF(AH10<=5,"Normal",IF(AH10=6,"Borderline","Abnormal"))) -> Borderline | AN10: =IF(AI10="","",IF(AI10<=3,"Normal",IF(AI10<=5,"Borderline","Abnormal"))) -> Normal | AO10: =IF(AJ10="","",IF(AJ10>=6,"Normal",IF(AJ10=5,"Borderline","Abnormal"))) -> Normal | AP10: =IF(A10="","",AF10+AG10+AH10+AI10) -> 14 | AQ10: =IF(A10="","",IF(AP10<=15,"Normal",IF(AP10<=19,"Borderline","Abnormal"))) -> Normal
A11: =Responses!A11 -> NqlaGMj | B11: =Responses!B11 -> ob0JgPM | C11: =Responses!C11 -> 46136.094 | D11: =Responses!D11 -> Bella Khalwanina Arastya | E11: =Responses!E11 -> XI-1 | F11: =Responses!F11 -> 18 | G11: =IF(Responses!G11="","",IF(Responses!G11="Benar",2,IF(Responses!G11="Agak Benar",1,0))) -> 2 | H11: =IF(Responses!H11="","",IF(Responses!H11="Benar",2,IF(Responses!H11="Agak Benar",1,0))) -> 0 | I11: =IF(Responses!I11="","",IF(Responses!I11="Benar",2,IF(Responses!I11="Agak Benar",1,0))) -> 1 | J11: =IF(Responses!J11="","",IF(Responses!J11="Benar",2,IF(Responses!J11="Agak Benar",1,0))) -> 1 | K11: =IF(Responses!K11="","",IF(Responses!K11="Benar",2,IF(Responses!K11="Agak Benar",1,0))) -> 0 | L11: =IF(Responses!L11="","",IF(Responses!L11="Benar",2,IF(Responses!L11="Agak Benar",1,0))) -> 2 | M11: =IF(Responses!M11="","",IF(Responses!M11="Tidak Benar",2,IF(Responses!M11="Agak Benar",1,0))) -> 0 | N11: =IF(Responses!N11="","",IF(Responses!N11="Benar",2,IF(Responses!N11="Agak Benar",1,0))) -> 1 | O11: =IF(Responses!O11="","",IF(Responses!O11="Benar",2,IF(Responses!O11="Agak Benar",1,0))) -> 2 | P11: =IF(Responses!P11="","",IF(Responses!P11="Benar",2,IF(Responses!P11="Agak Benar",1,0))) -> 1 | Q11: =IF(Responses!Q11="","",IF(Responses!Q11="Tidak Benar",2,IF(Responses!Q11="Agak Benar",1,0))) -> 0 | R11: =IF(Responses!R11="","",IF(Responses!R11="Benar",2,IF(Responses!R11="Agak Benar",1,0))) -> 0 | S11: =IF(Responses!S11="","",IF(Responses!S11="Benar",2,IF(Responses!S11="Agak Benar",1,0))) -> 1 | T11: =IF(Responses!T11="","",IF(Responses!T11="Tidak Benar",2,IF(Responses!T11="Agak Benar",1,0))) -> 1 | U11: =IF(Responses!U11="","",IF(Responses!U11="Benar",2,IF(Responses!U11="Agak Benar",1,0))) -> 0 | V11: =IF(Responses!V11="","",IF(Responses!V11="Benar",2,IF(Responses!V11="Agak Benar",1,0))) -> 1 | W11: =IF(Responses!W11="","",IF(Responses!W11="Benar",2,IF(Responses!W11="Agak Benar",1,0))) -> 2 | X11: =IF(Responses!X11="","",IF(Responses!X11="Benar",2,IF(Responses!X11="Agak Benar",1,0))) -> 0 | Y11: =IF(Responses!Y11="","",IF(Responses!Y11="Benar",2,IF(Responses!Y11="Agak Benar",1,0))) -> 0 | Z11: =IF(Responses!Z11="","",IF(Responses!Z11="Benar",2,IF(Responses!Z11="Agak Benar",1,0))) -> 2 | AA11: =IF(Responses!AA11="","",IF(Responses!AA11="Tidak Benar",2,IF(Responses!AA11="Agak Benar",1,0))) -> 0 | AB11: =IF(Responses!AB11="","",IF(Responses!AB11="Benar",2,IF(Responses!AB11="Agak Benar",1,0))) -> 0 | AC11: =IF(Responses!AC11="","",IF(Responses!AC11="Benar",2,IF(Responses!AC11="Agak Benar",1,0))) -> 1 | AD11: =IF(Responses!AD11="","",IF(Responses!AD11="Benar",2,IF(Responses!AD11="Agak Benar",1,0))) -> 1 | AE11: =IF(Responses!AE11="","",IF(Responses!AE11="Tidak Benar",2,IF(Responses!AE11="Agak Benar",1,0))) -> 0 | AF11: =IF(A11="","",I11+N11+S11+V11+AD11) -> 5 | AG11: =IF(A11="","",K11+M11+R11+X11+AB11) -> 0 | AH11: =IF(A11="","",H11+P11+U11+AA11+AE11) -> 1 | AI11: =IF(A11="","",L11+Q11+T11+Y11+AC11) -> 4 | AJ11: =IF(A11="","",G11+J11+O11+W11+Z11) -> 9 | AK11: =IF(AF11="","",IF(AF11<=5,"Normal",IF(AF11=6,"Borderline","Abnormal"))) -> Normal | AL11: =IF(AG11="","",IF(AG11<=3,"Normal",IF(AG11=4,"Borderline","Abnormal"))) -> Normal | AM11: =IF(AH11="","",IF(AH11<=5,"Normal",IF(AH11=6,"Borderline","Abnormal"))) -> Normal | AN11: =IF(AI11="","",IF(AI11<=3,"Normal",IF(AI11<=5,"Borderline","Abnormal"))) -> Borderline | AO11: =IF(AJ11="","",IF(AJ11>=6,"Normal",IF(AJ11=5,"Borderline","Abnormal"))) -> Normal | AP11: =IF(A11="","",AF11+AG11+AH11+AI11) -> 10 | AQ11: =IF(A11="","",IF(AP11<=15,"Normal",IF(AP11<=19,"Borderline","Abnormal"))) -> Normal
A12: =Responses!A12 -> e5QVkve | B12: =Responses!B12 -> RGZO2Ov | C12: =Responses!C12 -> 46136.094 | D12: =Responses!D12 -> Nabila Putri Herawati | E12: =Responses!E12 -> XI-1 | F12: =Responses!F12 -> 16 | G12: =IF(Responses!G12="","",IF(Responses!G12="Benar",2,IF(Responses!G12="Agak Benar",1,0))) -> 2 | H12: =IF(Responses!H12="","",IF(Responses!H12="Benar",2,IF(Responses!H12="Agak Benar",1,0))) -> 1 | I12: =IF(Responses!I12="","",IF(Responses!I12="Benar",2,IF(Responses!I12="Agak Benar",1,0))) -> 0 | J12: =IF(Responses!J12="","",IF(Responses!J12="Benar",2,IF(Responses!J12="Agak Benar",1,0))) -> 2 | K12: =IF(Responses!K12="","",IF(Responses!K12="Benar",2,IF(Responses!K12="Agak Benar",1,0))) -> 0 | L12: =IF(Responses!L12="","",IF(Responses!L12="Benar",2,IF(Responses!L12="Agak Benar",1,0))) -> 0 | M12: =IF(Responses!M12="","",IF(Responses!M12="Tidak Benar",2,IF(Responses!M12="Agak Benar",1,0))) -> 0 | N12: =IF(Responses!N12="","",IF(Responses!N12="Benar",2,IF(Responses!N12="Agak Benar",1,0))) -> 0 | O12: =IF(Responses!O12="","",IF(Responses!O12="Benar",2,IF(Responses!O12="Agak Benar",1,0))) -> 2 | P12: =IF(Responses!P12="","",IF(Responses!P12="Benar",2,IF(Responses!P12="Agak Benar",1,0))) -> 0 | Q12: =IF(Responses!Q12="","",IF(Responses!Q12="Tidak Benar",2,IF(Responses!Q12="Agak Benar",1,0))) -> 0 | R12: =IF(Responses!R12="","",IF(Responses!R12="Benar",2,IF(Responses!R12="Agak Benar",1,0))) -> 0 | S12: =IF(Responses!S12="","",IF(Responses!S12="Benar",2,IF(Responses!S12="Agak Benar",1,0))) -> 0 | T12: =IF(Responses!T12="","",IF(Responses!T12="Tidak Benar",2,IF(Responses!T12="Agak Benar",1,0))) -> 0 | U12: =IF(Responses!U12="","",IF(Responses!U12="Benar",2,IF(Responses!U12="Agak Benar",1,0))) -> 0 | V12: =IF(Responses!V12="","",IF(Responses!V12="Benar",2,IF(Responses!V12="Agak Benar",1,0))) -> 1 | W12: =IF(Responses!W12="","",IF(Responses!W12="Benar",2,IF(Responses!W12="Agak Benar",1,0))) -> 2 | X12: =IF(Responses!X12="","",IF(Responses!X12="Benar",2,IF(Responses!X12="Agak Benar",1,0))) -> 0 | Y12: =IF(Responses!Y12="","",IF(Responses!Y12="Benar",2,IF(Responses!Y12="Agak Benar",1,0))) -> 0 | Z12: =IF(Responses!Z12="","",IF(Responses!Z12="Benar",2,IF(Responses!Z12="Agak Benar",1,0))) -> 2 | AA12: =IF(Responses!AA12="","",IF(Responses!AA12="Tidak Benar",2,IF(Responses!AA12="Agak Benar",1,0))) -> 0 | AB12: =IF(Responses!AB12="","",IF(Responses!AB12="Benar",2,IF(Responses!AB12="Agak Benar",1,0))) -> 0 | AC12: =IF(Responses!AC12="","",IF(Responses!AC12="Benar",2,IF(Responses!AC12="Agak Benar",1,0))) -> 0 | AD12: =IF(Responses!AD12="","",IF(Responses!AD12="Benar",2,IF(Responses!AD12="Agak Benar",1,0))) -> 1 | AE12: =IF(Responses!AE12="","",IF(Responses!AE12="Tidak Benar",2,IF(Responses!AE12="Agak Benar",1,0))) -> 0 | AF12: =IF(A12="","",I12+N12+S12+V12+AD12) -> 2 | AG12: =IF(A12="","",K12+M12+R12+X12+AB12) -> 0 | AH12: =IF(A12="","",H12+P12+U12+AA12+AE12) -> 1 | AI12: =IF(A12="","",L12+Q12+T12+Y12+AC12) -> 0 | AJ12: =IF(A12="","",G12+J12+O12+W12+Z12) -> 10 | AK12: =IF(AF12="","",IF(AF12<=5,"Normal",IF(AF12=6,"Borderline","Abnormal"))) -> Normal | AL12: =IF(AG12="","",IF(AG12<=3,"Normal",IF(AG12=4,"Borderline","Abnormal"))) -> Normal | AM12: =IF(AH12="","",IF(AH12<=5,"Normal",IF(AH12=6,"Borderline","Abnormal"))) -> Normal | AN12: =IF(AI12="","",IF(AI12<=3,"Normal",IF(AI12<=5,"Borderline","Abnormal"))) -> Normal | AO12: =IF(AJ12="","",IF(AJ12>=6,"Normal",IF(AJ12=5,"Borderline","Abnormal"))) -> Normal | AP12: =IF(A12="","",AF12+AG12+AH12+AI12) -> 3 | AQ12: =IF(A12="","",IF(AP12<=15,"Normal",IF(AP12<=19,"Borderline","Abnormal"))) -> Normal
A13: =Responses!A13 -> kbe2MX6 | B13: =Responses!B13 -> dWZ7pEd | C13: =Responses!C13 -> 46136.094 | D13: =Responses!D13 -> Arsyita | E13: =Responses!E13 -> XI-1 | F13: =Responses!F13 -> 16 | G13: =IF(Responses!G13="","",IF(Responses!G13="Benar",2,IF(Responses!G13="Agak Benar",1,0))) -> 2 | H13: =IF(Responses!H13="","",IF(Responses!H13="Benar",2,IF(Responses!H13="Agak Benar",1,0))) -> 0 | I13: =IF(Responses!I13="","",IF(Responses!I13="Benar",2,IF(Responses!I13="Agak Benar",1,0))) -> 1 | J13: =IF(Responses!J13="","",IF(Responses!J13="Benar",2,IF(Responses!J13="Agak Benar",1,0))) -> 2 | K13: =IF(Responses!K13="","",IF(Responses!K13="Benar",2,IF(Responses!K13="Agak Benar",1,0))) -> 1 | L13: =IF(Responses!L13="","",IF(Responses!L13="Benar",2,IF(Responses!L13="Agak Benar",1,0))) -> 0 | M13: =IF(Responses!M13="","",IF(Responses!M13="Tidak Benar",2,IF(Responses!M13="Agak Benar",1,0))) -> 1 | N13: =IF(Responses!N13="","",IF(Responses!N13="Benar",2,IF(Responses!N13="Agak Benar",1,0))) -> 0 | O13: =IF(Responses!O13="","",IF(Responses!O13="Benar",2,IF(Responses!O13="Agak Benar",1,0))) -> 2 | P13: =IF(Responses!P13="","",IF(Responses!P13="Benar",2,IF(Responses!P13="Agak Benar",1,0))) -> 0 | Q13: =IF(Responses!Q13="","",IF(Responses!Q13="Tidak Benar",2,IF(Responses!Q13="Agak Benar",1,0))) -> 0 | R13: =IF(Responses!R13="","",IF(Responses!R13="Benar",2,IF(Responses!R13="Agak Benar",1,0))) -> 0 | S13: =IF(Responses!S13="","",IF(Responses!S13="Benar",2,IF(Responses!S13="Agak Benar",1,0))) -> 1 | T13: =IF(Responses!T13="","",IF(Responses!T13="Tidak Benar",2,IF(Responses!T13="Agak Benar",1,0))) -> 0 | U13: =IF(Responses!U13="","",IF(Responses!U13="Benar",2,IF(Responses!U13="Agak Benar",1,0))) -> 1 | V13: =IF(Responses!V13="","",IF(Responses!V13="Benar",2,IF(Responses!V13="Agak Benar",1,0))) -> 0 | W13: =IF(Responses!W13="","",IF(Responses!W13="Benar",2,IF(Responses!W13="Agak Benar",1,0))) -> 1 | X13: =IF(Responses!X13="","",IF(Responses!X13="Benar",2,IF(Responses!X13="Agak Benar",1,0))) -> 0 | Y13: =IF(Responses!Y13="","",IF(Responses!Y13="Benar",2,IF(Responses!Y13="Agak Benar",1,0))) -> 0 | Z13: =IF(Responses!Z13="","",IF(Responses!Z13="Benar",2,IF(Responses!Z13="Agak Benar",1,0))) -> 1 | AA13: =IF(Responses!AA13="","",IF(Responses!AA13="Tidak Benar",2,IF(Responses!AA13="Agak Benar",1,0))) -> 1 | AB13: =IF(Responses!AB13="","",IF(Responses!AB13="Benar",2,IF(Responses!AB13="Agak Benar",1,0))) -> 0 | AC13: =IF(Responses!AC13="","",IF(Responses!AC13="Benar",2,IF(Responses!AC13="Agak Benar",1,0))) -> 0 | AD13: =IF(Responses!AD13="","",IF(Responses!AD13="Benar",2,IF(Responses!AD13="Agak Benar",1,0))) -> 1 | AE13: =IF(Responses!AE13="","",IF(Responses!AE13="Tidak Benar",2,IF(Responses!AE13="Agak Benar",1,0))) -> 1 | AF13: =IF(A13="","",I13+N13+S13+V13+AD13) -> 3 | AG13: =IF(A13="","",K13+M13+R13+X13+AB13) -> 2 | AH13: =IF(A13="","",H13+P13+U13+AA13+AE13) -> 3 | AI13: =IF(A13="","",L13+Q13+T13+Y13+AC13) -> 0 | AJ13: =IF(A13="","",G13+J13+O13+W13+Z13) -> 8 | AK13: =IF(AF13="","",IF(AF13<=5,"Normal",IF(AF13=6,"Borderline","Abnormal"))) -> Normal | AL13: =IF(AG13="","",IF(AG13<=3,"Normal",IF(AG13=4,"Borderline","Abnormal"))) -> Normal | AM13: =IF(AH13="","",IF(AH13<=5,"Normal",IF(AH13=6,"Borderline","Abnormal"))) -> Normal | AN13: =IF(AI13="","",IF(AI13<=3,"Normal",IF(AI13<=5,"Borderline","Abnormal"))) -> Normal | AO13: =IF(AJ13="","",IF(AJ13>=6,"Normal",IF(AJ13=5,"Borderline","Abnormal"))) -> Normal | AP13: =IF(A13="","",AF13+AG13+AH13+AI13) -> 8 | AQ13: =IF(A13="","",IF(AP13<=15,"Normal",IF(AP13<=19,"Borderline","Abnormal"))) -> Normal
... A127: =Responses!A127 -> Gepxgbz | B127: =Responses!B127 -> zxWENP0 | C127: =Responses!C127 -> 46136.156 | D127: =Responses!D127 -> Safira Rahma Rajabiya | E127: =Responses!E127 -> XI-2 | F127: =Responses!F127 -> 16 | G127: =IF(Responses!G127="","",IF(Responses!G127="Benar",2,IF(Responses!G127="Agak Benar",1,0))) -> 2 | H127: =IF(Responses!H127="","",IF(Responses!H127="Benar",2,IF(Responses!H127="Agak Benar",1,0))) -> 0 | I127: =IF(Responses!I127="","",IF(Responses!I127="Benar",2,IF(Responses!I127="Agak Benar",1,0))) -> 1 | J127: =IF(Responses!J127="","",IF(Responses!J127="Benar",2,IF(Responses!J127="Agak Benar",1,0))) -> 1 | K127: =IF(Responses!K127="","",IF(Responses!K127="Benar",2,IF(Responses!K127="Agak Benar",1,0))) -> 1 | L127: =IF(Responses!L127="","",IF(Responses!L127="Benar",2,IF(Responses!L127="Agak Benar",1,0))) -> 0 | M127: =IF(Responses!M127="","",IF(Responses!M127="Tidak Benar",2,IF(Responses!M127="Agak Benar",1,0))) -> 1 | N127: =IF(Responses!N127="","",IF(Responses!N127="Benar",2,IF(Responses!N127="Agak Benar",1,0))) -> 1 | O127: =IF(Responses!O127="","",IF(Responses!O127="Benar",2,IF(Responses!O127="Agak Benar",1,0))) -> 2 | P127: =IF(Responses!P127="","",IF(Responses!P127="Benar",2,IF(Responses!P127="Agak Benar",1,0))) -> 1 | Q127: =IF(Responses!Q127="","",IF(Responses!Q127="Tidak Benar",2,IF(Responses!Q127="Agak Benar",1,0))) -> 0 | R127: =IF(Responses!R127="","",IF(Responses!R127="Benar",2,IF(Responses!R127="Agak Benar",1,0))) -> 0 | S127: =IF(Responses!S127="","",IF(Responses!S127="Benar",2,IF(Responses!S127="Agak Benar",1,0))) -> 1 | T127: =IF(Responses!T127="","",IF(Responses!T127="Tidak Benar",2,IF(Responses!T127="Agak Benar",1,0))) -> 1 | U127: =IF(Responses!U127="","",IF(Responses!U127="Benar",2,IF(Responses!U127="Agak Benar",1,0))) -> 0 | V127: =IF(Responses!V127="","",IF(Responses!V127="Benar",2,IF(Responses!V127="Agak Benar",1,0))) -> 1 | W127: =IF(Responses!W127="","",IF(Responses!W127="Benar",2,IF(Responses!W127="Agak Benar",1,0))) -> 2 | X127: =IF(Responses!X127="","",IF(Responses!X127="Benar",2,IF(Responses!X127="Agak Benar",1,0))) -> 0 | Y127: =IF(Responses!Y127="","",IF(Responses!Y127="Benar",2,IF(Responses!Y127="Agak Benar",1,0))) -> 0 | Z127: =IF(Responses!Z127="","",IF(Responses!Z127="Benar",2,IF(Responses!Z127="Agak Benar",1,0))) -> 2 | AA127: =IF(Responses!AA127="","",IF(Responses!AA127="Tidak Benar",2,IF(Responses!AA127="Agak Benar",1,0))) -> 0 | AB127: =IF(Responses!AB127="","",IF(Responses!AB127="Benar",2,IF(Responses!AB127="Agak Benar",1,0))) -> 0 | AC127: =IF(Responses!AC127="","",IF(Responses!AC127="Benar",2,IF(Responses!AC127="Agak Benar",1,0))) -> 1 | AD127: =IF(Responses!AD127="","",IF(Responses!AD127="Benar",2,IF(Responses!AD127="Agak Benar",1,0))) -> 2 | AE127: =IF(Responses!AE127="","",IF(Responses!AE127="Tidak Benar",2,IF(Responses!AE127="Agak Benar",1,0))) -> 0 | AF127: =IF(A127="","",I127+N127+S127+V127+AD127) -> 6 | AG127: =IF(A127="","",K127+M127+R127+X127+AB127) -> 2 | AH127: =IF(A127="","",H127+P127+U127+AA127+AE127) -> 1 | AI127: =IF(A127="","",L127+Q127+T127+Y127+AC127) -> 2 | AJ127: =IF(A127="","",G127+J127+O127+W127+Z127) -> 9 | AK127: =IF(AF127="","",IF(AF127<=5,"Normal",IF(AF127=6,"Borderline","Abnormal"))) -> Borderline | AL127: =IF(AG127="","",IF(AG127<=3,"Normal",IF(AG127=4,"Borderline","Abnormal"))) -> Normal | AM127: =IF(AH127="","",IF(AH127<=5,"Normal",IF(AH127=6,"Borderline","Abnormal"))) -> Normal | AN127: =IF(AI127="","",IF(AI127<=3,"Normal",IF(AI127<=5,"Borderline","Abnormal"))) -> Normal | AO127: =IF(AJ127="","",IF(AJ127>=6,"Normal",IF(AJ127=5,"Borderline","Abnormal"))) -> Normal | AP127: =IF(A127="","",AF127+AG127+AH127+AI127) -> 11 | AQ127: =IF(A127="","",IF(AP127<=15,"Normal",IF(AP127<=19,"Borderline","Abnormal"))) -> Normal

Sheet IAA_Scores
A1: Submission ID | B1: Respondent ID | C1: Submitted At | D1: Nama | E1: Kelas | F1: Umur | G1: Skor IAA Q1 | H1: Skor IAA Q2 | I1: Skor IAA Q3 | J1: Skor IAA Q4 | K1: Skor IAA Q5 | L1: Skor IAA Q6 | M1: Skor IAA Q7 | N1: Skor IAA Q8 | O1: Skor IAA Q9 | P1: Skor IAA Q10 | Q1: Skor IAA Q11 | R1: Skor IAA Q12 | S1: Skor IAA Q13 | T1: Skor IAA Q14 | U1: Skor IAA Q15 | V1: Skor IAA Q16 | W1: Skor IAA Q17 | X1: Skor IAA Q18 | Y1: Total Skor IAA | Z1: Status IAA
